<robot name="box_bot">

  <material name="red">
      <color rgba="1.0 0.0 0.0 1"/>
  </material>

  <material name="green_light">
      <color rgba="0.0 1.0 0.0 1"/>
  </material>

  <material name="green_dark">
    <color rgba="0.0 0.5 0.0 1"/>
  </material>

  <material name="blue">
      <color rgba="0.0 0.0 1.0 1"/>
  </material>

  <material name="black">
      <color rgba="0.0 0.0 0.0 1"/>
  </material>

  <material name="white">
      <color rgba="1.0 1.0 1.0 1"/>
  </material>

 <material name="box_bot_blue">
      <color rgba="0.088656 0.428691 0.491021 1"/>
  </material>

  <link name="base_link">
  </link>

  <link name="chassis">
    <visual>
      <geometry>
        <box size="0.1 0.1 0.1"/>
      </geometry>
      <material name="box_bot_blue"/>
    </visual>
  </link>

  <link name="left_wheel">
    <visual>
      <origin rpy="0 1.5707 1.5707" xyz="0 0 0"/>
      <geometry>
        <cylinder radius="0.035" length="0.001"/>
      </geometry>
      <material name="black"/>
    </visual>
  </link>

  <link name="right_wheel">
    <visual>
      <origin rpy="0 1.5707 1.5707" xyz="0 0 0"/>
      <geometry>
        <cylinder radius="0.035" length="0.001"/>
      </geometry>
      <material name="white"/>
    </visual>
  </link>

  <link name="front_yaw_link">
    <visual>
      <geometry>
        <cylinder radius="0.010" length="0.005"/>
      </geometry>
      <material name="blue"/>
    </visual>
  </link>

  <link name="back_yaw_link">
    <visual>
      <geometry>
        <cylinder radius="0.010" length="0.005"/>
      </geometry>
      <material name="blue"/>
    </visual>
  </link>

  <link name="front_roll_link">
    <visual>
      <geometry>
        <cylinder radius="0.010" length="0.005"/>
      </geometry>
      <material name="red"/>
    </visual>
  </link>

  <link name="back_roll_link">
    <visual>
      <geometry>
        <cylinder radius="0.010" length="0.005"/>
      </geometry>
      <material name="red"/>
    </visual>
  </link>

  <link name="front_pitch_link">
    <visual>
      <geometry>
        <sphere radius="0.010"/>
      </geometry>
      <material name="green_dark"/>
    </visual>
  </link>

  <link name="back_pitch_link">
    <visual>
      <geometry>
        <sphere radius="0.010"/>
      </geometry>
      <material name="green_light"/>
    </visual>
  </link>

  <joint name="front_pitch_joint" type="continuous">
    <origin xyz="0 0 0" rpy="0 0 0"/>
    <parent link="front_roll_link"/>
    <child link="front_pitch_link"/>
    <axis xyz="0 1 0"/>
    <limit effort="1000.0" velocity="100.0" />
    <dynamics damping="0.0" friction="0.1"/>
  </joint>

  <joint name="back_pitch_joint" type="continuous">
    <origin xyz="0 0 0" rpy="0 0 0"/>
    <parent link="back_roll_link"/>
    <child link="back_pitch_link"/>
    <axis xyz="0 1 0"/>
    <limit effort="1000.0" velocity="100.0" />
    <dynamics damping="0.0" friction="0.1"/>
  </joint>

  <joint name="front_roll_joint" type="continuous">
    <origin xyz="0 0 0" rpy="0 0 0"/>
    <parent link="front_yaw_link"/>
    <child link="front_roll_link"/>
    <axis xyz="1 0 0"/>
    <limit effort="1000.0" velocity="100.0" />
    <dynamics damping="0.0" friction="0.1"/>
  </joint>

  <joint name="back_roll_joint" type="continuous">
    <origin xyz="0 0 0" rpy="0 0 0"/>
    <parent link="back_yaw_link"/>
    <child link="back_roll_link"/>
    <axis xyz="1 0 0"/>
    <limit effort="1000.0" velocity="100.0" />
    <dynamics damping="0.0" friction="0.1"/>
  </joint>

  <joint name="front_yaw_joint" type="continuous">
    <origin xyz="0.04 0 -0.05" rpy="0 0 0"/>
    <parent link="chassis"/>
    <child link="front_yaw_link"/>
    <axis xyz="0 0 1"/>
    <limit effort="1000.0" velocity="100.0" />
    <dynamics damping="0.0" friction="0.1"/>
  </joint>

  <joint name="back_yaw_joint" type="continuous">
    <origin xyz="-0.04 0 -0.05" rpy="0 0 0"/>
    <parent link="chassis"/>
    <child link="back_yaw_link"/>
    <axis xyz="0 0 1"/>
    <limit effort="1000.0" velocity="100.0" />
    <dynamics damping="0.0" friction="0.1"/>
  </joint>

  <joint name="joint_right_wheel" type="continuous">
    <origin xyz="0 -0.05 -0.025" rpy="0 0 0"/>
    <parent link="chassis"/>
    <child link="right_wheel"/>
    <axis xyz="0 1 0" rpy="0 0 0"/>
    <limit effort="1000.0" velocity="100.0" />
    <dynamics damping="0.0" friction="0.1"/>
  </joint>

  <joint name="joint_left_wheel" type="continuous">
    <origin xyz="0 0.05 -0.025" rpy="0 0 0"/>
    <parent link="chassis"/>
    <child link="left_wheel"/>
    <axis xyz="0 1 0"/>
    <limit effort="1000.0" velocity="100.0" />
    <dynamics damping="0.0" friction="0.1"/>
  </joint>

  <joint name="base_link_joint" type="fixed">
    <origin xyz="0 0 0" rpy="0 0 0"/>
    <parent link="base_link"/>
    <child link="chassis"/>
  </joint>

</robot>