<?xml version="1.0"?>
<robot name="box_bot">
        
  <material name="red">
      <color rgba="1.0 0.0 0.0 1"/>
  </material>

  <material name="green_light">
      <color rgba="0.0 1.0 0.0 1"/>
  </material>

  <material name="green_dark">
    <color rgba="0.0 0.5 0.0 1"/>
  </material>

  <material name="yellow">
      <color rgba="1.0 1.0 0.0 1"/>
  </material>

  <material name="blue">
      <color rgba="0.0 0.0 1.0 1"/>
  </material>

  <link name="base_link">
  </link>


  <!-- Body -->
  <link name="chassis">
    <visual>
      <geometry>
        <mesh filename="package://my_box_bot_description/meshes/cute_cube.dae" scale="0.1 0.1 0.1"/>
      </geometry>
    </visual>

    <collision>
      <geometry>
        <box size="0.1 0.1 0.1"/>
      </geometry>
    </collision>

    <inertial>
      <mass value="0.5"/>
      <origin rpy="0 0 0" xyz="0 0 0"/>
      <inertia ixx="0.0008333333333333335" ixy="0" ixz="0" iyy="0.0008333333333333335" iyz="0" izz="0.0008333333333333335"/>
    </inertial>

  </link>

  <joint name="base_link_joint" type="fixed">
    <origin rpy="0 0 0" xyz="0 0 0" />
    <parent link="base_link" />
    <child link="chassis" />
  </joint>

  <!-- Wheel Left -->
  <link name="left_wheel">      
      <visual>
        <origin rpy="0 1.5707 1.5707" xyz="0 0 0"/>
        <geometry>
          <cylinder length="0.001" radius="0.035"/>
        </geometry>
        <material name="red"/>
      </visual>

      <collision>
        <origin rpy="0 1.5707 1.5707" xyz="0 0 0"/>
        <geometry>
          <cylinder length="0.001" radius="0.035"/>
        </geometry>
      </collision>

      <inertial>
        <origin rpy="0 1.5707 1.5707" xyz="0 0 0"/>
        <mass value="0.05"/>
        <inertia ixx="1.531666666666667e-05" ixy="0" ixz="0" iyy="1.531666666666667e-05" iyz="0" izz="3.0625000000000006e-05"/>
      </inertial>

  </link>

  <gazebo reference="left_wheel">
    <collision>
        <surface>
        <friction>
            <ode>
            <mu>10.0</mu>
            <mu2>10.0</mu2>
            </ode>
        </friction>
        <contact>
            <ode>
            <kp>10000000.0</kp>
            <kd>10000000.0</kd>
            </ode>
        </contact>
        </surface>
    </collision>
  </gazebo>


  <joint name="joint_left_wheel" type="continuous">
    <origin rpy="0 0 0" xyz="0 0.05 -0.025"/>
    <child link="left_wheel"/>
    <parent link="chassis"/>
    <axis rpy="0 0 0" xyz="0 1 0"/>
    <limit effort="10000" velocity="1000"/>
    <joint_properties damping="1.0" friction="1.0"/>
  </joint>

  <!-- Wheel Right -->
  <link name="right_wheel">      
      <visual>
        <origin rpy="0 1.5707 1.5707" xyz="0 0 0"/>
        <geometry>
          <cylinder length="0.001" radius="0.035"/>
        </geometry>
        <material name="yellow"/>
      </visual>

      <collision>
        <origin rpy="0 1.5707 1.5707" xyz="0 0 0"/>
        <geometry>
          <cylinder length="0.001" radius="0.035"/>
        </geometry>
      </collision>

      <inertial>
        <origin rpy="0 1.5707 1.5707" xyz="0 0 0"/>
        <mass value="0.05"/>
        <inertia ixx="1.531666666666667e-05" ixy="0" ixz="0" iyy="1.531666666666667e-05" iyz="0" izz="3.0625000000000006e-05"/>
      </inertial>
  </link>

  <gazebo reference="right_wheel">
    <collision>
        <surface>
        <friction>
            <ode>
            <mu>10.0</mu>
            <mu2>10.0</mu2>
            </ode>
        </friction>
        <contact>
            <ode>
            <kp>10000000.0</kp>
            <kd>10000000.0</kd>
            </ode>
        </contact>
        </surface>
    </collision>
  </gazebo>

  <joint name="joint_right_wheel" type="continuous">  
    <origin rpy="0 0 0" xyz="0 -0.05 -0.025"/>
    <child link="right_wheel"/>
    <parent link="chassis"/>
    <axis rpy="0 0 0" xyz="0 1 0"/>
    <limit effort="10000" velocity="1000"/>
    <joint_properties damping="1.0" friction="1.0"/>
  </joint>


  <!-- Caster Wheel Front -->
  <link name="front_yaw_link">
      <visual>
        <origin rpy="0 1.5707 1.5707" xyz="0 0 0"/>
        <geometry>          
          <cylinder length="0.001" radius="0.0045000000000000005"/>
        </geometry>
        <material name="blue"/>
      </visual>

      <collision>
        <origin rpy="0 1.5707 1.5707" xyz="0 0 0"/>
        <geometry>
          <cylinder length="0.001" radius="0.0045000000000000005"/>
        </geometry>
      </collision>

      <inertial>
          <origin rpy="0 1.5707 1.5707" xyz="0 0 0"/>
          <mass value="0.001"/>
          <inertia ixx="5.145833333333334e-09" ixy="0" ixz="0" iyy="5.145833333333334e-09" iyz="0" izz="1.0125000000000003e-08"/>
      </inertial>

  </link>

  <joint name="front_yaw_joint" type="continuous">
    <origin rpy="0 0 0" xyz="0.04 0 -0.05" />
    <parent link="chassis" />
    <child link="front_yaw_link" />
    <axis xyz="0 0 1" />
    <limit effort="1000.0" velocity="100.0" />
    <dynamics damping="0.0" friction="0.1"/>
  </joint>

  <link name="front_roll_link">
      <visual>
        <origin rpy="0 1.5707 1.5707" xyz="0 0 0"/>
        <geometry>
          <cylinder length="0.001" radius="0.0045000000000000005"/>
        </geometry>
        <material name="red"/>
      </visual>

      <collision>
        <origin rpy="0 1.5707 1.5707" xyz="0 0 0"/>
        <geometry>
          <cylinder length="0.001" radius="0.0045000000000000005"/>
        </geometry>
      </collision>

      <inertial>
          <origin rpy="0 1.5707 1.5707" xyz="0 0 0"/>
          <mass value="0.001"/>
          <inertia ixx="5.145833333333334e-09" ixy="0" ixz="0" iyy="5.145833333333334e-09" iyz="0" izz="1.0125000000000003e-08"/>
      </inertial>
  </link>

  <joint name="front_roll_joint" type="continuous">
    <origin rpy="0 0 0" xyz="0 0 0" />
    <parent link="front_yaw_link" />
    <child link="front_roll_link" />
    <axis xyz="1 0 0" />
    <limit effort="1000.0" velocity="100.0" />
    <dynamics damping="0.0" friction="0.1"/>
  </joint>

  <link name="front_pitch_link">
    <visual>
      <origin rpy="0 1.5707 1.5707" xyz="0 0 0"/>
      <geometry>
        <sphere radius="0.010"/>
      </geometry>
      <material name="green_dark"/>
    </visual>

    <collision>
      <origin rpy="0 1.5707 1.5707" xyz="0 0 0"/>
      <geometry>
        <sphere radius="0.010"/>
      </geometry>
    </collision>

    <inertial>
        <origin rpy="0 1.5707 1.5707" xyz="0 0 0"/>
        <mass value="0.001"/>
        <inertia ixx="4e-08" ixy="0" ixz="0" iyy="4e-08" iyz="0" izz="4e-08"/>
    </inertial>
  </link>

  <gazebo reference="front_pitch_link">
    <collision>
        <surface>
        <friction>
            <ode>
            <mu>0.5</mu>
            <mu2>0.5</mu2>
            </ode>
        </friction>
        <contact>
            <ode>
            <kp>10000000.0</kp>
            <kd>10000000.0</kd>
            </ode>
        </contact>
        </surface>
    </collision>
  </gazebo>

  <joint name="front_pitch_joint" type="continuous">
    <origin rpy="0 0 0" xyz="0 0 0" />
    <parent link="front_roll_link" />
    <child link="front_pitch_link" />
    <axis xyz="0 1 0" />
    <limit effort="1000.0" velocity="100.0" />
    <dynamics damping="0.0" friction="0.1"/>
  </joint>

<!-- Caster Wheel Back -->
  <link name="back_yaw_link">
    <visual>
        <origin rpy="0 1.5707 1.5707" xyz="0 0 0"/>
        <geometry>
          <cylinder length="0.001" radius="0.0045000000000000005"/>
        </geometry>
        <material name="blue"/>
      </visual>

      <collision>
        <origin rpy="0 1.5707 1.5707" xyz="0 0 0"/>
        <geometry>
          <cylinder length="0.001" radius="0.0045000000000000005"/>
        </geometry>
      </collision>

      <inertial>
          <origin rpy="0 1.5707 1.5707" xyz="0 0 0"/>
          <mass value="0.001"/>
          <inertia ixx="5.145833333333334e-09" ixy="0" ixz="0" iyy="5.145833333333334e-09" iyz="0" izz="1.0125000000000003e-08"/>
      </inertial>
  </link>

  <joint name="back_yaw_joint" type="continuous">
    <origin rpy="0 0 0" xyz="-0.04 0 -0.05" />
    <parent link="chassis" />
    <child link="back_yaw_link" />
    <axis xyz="0 0 1" />
    <limit effort="1000.0" velocity="100.0" />
    <dynamics damping="0.0" friction="0.1"/>
  </joint>


  <link name="back_roll_link">
      <visual>
        <origin rpy="0 1.5707 1.5707" xyz="0 0 0"/>
        <geometry>
          <cylinder length="0.001" radius="0.0045000000000000005"/>
        </geometry>
        <material name="red"/>
      </visual>

      <collision>
        <origin rpy="0 1.5707 1.5707" xyz="0 0 0"/>
        <geometry>
          <cylinder length="0.001" radius="0.0045000000000000005"/>
        </geometry>
      </collision>

      <inertial>
          <origin rpy="0 1.5707 1.5707" xyz="0 0 0"/>
          <mass value="0.001"/>
          <inertia ixx="5.145833333333334e-09" ixy="0" ixz="0" iyy="5.145833333333334e-09" iyz="0" izz="1.0125000000000003e-08"/>
      </inertial>
  </link>

  <joint name="back_roll_joint" type="continuous">
    <origin rpy="0 0 0" xyz="0 0 0" />
    <parent link="back_yaw_link" />
    <child link="back_roll_link" />
    <axis xyz="1 0 0" />
    <limit effort="1000.0" velocity="100.0" />
    <dynamics damping="0.0" friction="0.1"/>
  </joint>


  <link name="back_pitch_link">
    <visual>
      <origin rpy="0 1.5707 1.5707" xyz="0 0 0"/>
      <geometry>
        <sphere radius="0.010"/>
      </geometry>
      <material name="green_light"/>
    </visual>

    <collision>
      <origin rpy="0 1.5707 1.5707" xyz="0 0 0"/>
      <geometry>
        <sphere radius="0.010"/>
      </geometry>
    </collision>

    <inertial>
        <origin rpy="0 1.5707 1.5707" xyz="0 0 0"/>
        <mass value="0.001"/>
        <inertia ixx="4e-08" ixy="0" ixz="0" iyy="4e-08" iyz="0" izz="4e-08"/>
    </inertial>
  </link>

  <gazebo reference="back_pitch_link">
    <collision>
        <surface>
        <friction>
            <ode>
            <mu>0.5</mu>
            <mu2>0.5</mu2>
            </ode>
        </friction>
        <contact>
            <ode>
            <kp>10000000.0</kp>
            <kd>10000000.0</kd>
            </ode>
        </contact>
        </surface>
    </collision>
  </gazebo>

  <joint name="back_pitch_joint" type="continuous">
    <origin rpy="0 0 0" xyz="0 0 0" />
    <parent link="back_roll_link" />
    <child link="back_pitch_link" />
    <axis xyz="0 1 0" />
    <limit effort="1000.0" velocity="100.0" />
    <dynamics damping="0.0" friction="0.1"/>
  </joint>
  

  <!-- Laser Position Control -->

  <link name="laser_scan_link">
    <visual>
      <origin rpy="0 0 0" xyz="0 0 0"/>
      <geometry>
        <box size="0.02 0.02 0.02"/>
      </geometry>
    </visual>

    <collision>
       <origin rpy="0 0 0" xyz="0 0 0.0204"/>
      <geometry>
        <box size="0.02 0.02 0.02"/>
      </geometry>
    </collision>

    <inertial>

      <mass value="0.01"/>
      <origin rpy="0 0 0" xyz="0 0 0.0204"/>
      <inertia ixx="6.066578520833334e-06" ixy="0" ixz="0" iyy="6.072950163333333e-06" iyz="0" izz="9.365128684166666e-06"/>
    </inertial>
  </link>

  <joint name="laser_scan_link_joint" type="prismatic">
    <origin rpy="0 0 0" xyz="0.0 0.0 0.05"/>
    <parent link="chassis"/>
    <child link="laser_scan_link"/>
    <axis xyz="0 0 1"/>
    <limit lower="-0.1" upper="0.0" effort="20.0" velocity="2.0"/>
    <dynamics damping="0.1" friction="1.0"/>
  </joint>

  <link name="laser_scan_frame">
  </link>

  <joint name="laser_scan_frame_joint" type="fixed">
    <origin rpy="0 0 0" xyz="0 0 0.03"/>
    <parent link="laser_scan_link"/>
    <child link="laser_scan_frame"/>
    <axis xyz="0 0 0"/>
  </joint>

  <!-- Visual Laser Model to be rotated -->
  <link name="laser_scan_model_link">
    <visual>
      <origin rpy="0 0 0" xyz="0 0 0"/>
      <geometry>
        <mesh filename="package://my_box_bot_description/meshes/sensors/rplidar.dae" scale="1.0 1.0 1.0"/>
      </geometry>
    </visual>

    <collision>
       <origin rpy="0 0 0" xyz="0 0 0.0204"/>
      <geometry>
        <cylinder length="0.0408" radius="0.037493"/>
      </geometry>
    </collision>

    <inertial>

      <mass value="0.01"/>
      <origin rpy="0 0 0" xyz="0 0 0.0204"/>
      <inertia ixx="6.066578520833334e-06" ixy="0" ixz="0" iyy="6.072950163333333e-06" iyz="0" izz="9.365128684166666e-06"/>
    </inertial>
  </link>

  <joint name="laser_scan_model_link_joint" type="continuous">
    <origin rpy="0 0 0" xyz="0.0 0.0 0.0"/>
    <parent link="laser_scan_link"/>
    <child link="laser_scan_model_link"/>
    <axis xyz="0 0 1"/>
    <limit effort="10.0" velocity="2.0"/>
    <dynamics friction="0.01"/>
  </joint>

  <!-- PLUGINS -->

  <!-- Joint State Publisher Plugin -->
  <gazebo>
    <plugin filename="gz-sim-joint-state-publisher-system"
            name="gz::sim::systems::JointStatePublisher">
        <topic>/joint_states</topic>
        <update_rate>30</update_rate>
        <!-- Publish the state of these joints -->
        <joint_name>joint_left_wheel</joint_name>
        <joint_name>joint_right_wheel</joint_name>
        <joint_name>front_yaw_joint</joint_name>
        <joint_name>back_yaw_joint</joint_name>
        <joint_name>front_roll_joint</joint_name>
        <joint_name>back_roll_joint</joint_name>
        <joint_name>front_pitch_joint</joint_name>
        <joint_name>back_pitch_joint</joint_name>
    </plugin>
  </gazebo>  

  <!-- Differential Drive Plugin -->
  <gazebo>
    <plugin
        filename="gz-sim-diff-drive-system"
        name="gz::sim::systems::DiffDrive">
        <left_joint>joint_left_wheel</left_joint>
        <right_joint>joint_right_wheel</right_joint>
        <wheel_separation>0.1</wheel_separation>
        <wheel_radius>0.035</wheel_radius>
        <topic>cmd_vel</topic>
        <publish_odom>true</publish_odom>
        <publish_odom_tf>true</publish_odom_tf>
        <publish_wheel_tf>true</publish_wheel_tf>
        <odom_topic>odom</odom_topic>
        <tf_topic>tf</tf_topic>
        <frame_id>odom</frame_id>
        <child_frame_id>base_link</child_frame_id>
    </plugin>
  </gazebo>

  <!-- ros2_control config -->
  <ros2_control name="GazeboSimSystem" type="system">
    <hardware>
        <!-- Gazebo Sim integration plugin -->
        <plugin>gz_ros2_control/GazeboSimSystem</plugin>
    </hardware>

    <joint name="laser_scan_link_joint">
      <command_interface name="position">
        <param name="min">-0.05</param>
        <param name="max">0.0</param>
      </command_interface>
      <state_interface name="position"/>
      <state_interface name="velocity"/>
      <state_interface name="effort"/>
    </joint>

    <joint name="laser_scan_model_link_joint">
        <command_interface name="velocity">
          <param name="min">0.0</param>
          <param name="max">2.0</param>
        </command_interface>
        <state_interface name="position"/>
        <state_interface name="velocity"/>
        <state_interface name="effort"/>
      </joint>
   </ros2_control>

   <!-- Gazebo Sim system plugin that boots the controller manager and parses the ros2_control tags -->
   <gazebo>
    <plugin filename="gz_ros2_control-system"
            name="gz_ros2_control::GazeboSimROS2ControlPlugin">

        <!-- Controller configuration YAML file -->
        <parameters>$(find my_box_bot_description)/config/controller_position_velocity.yaml</parameters>

    </plugin>
   </gazebo>

<!-- Enable Sensors in Gazebo Sim -->
<gazebo>
    <plugin filename="gz-sim-sensors-system" name="gz::sim::systems::Sensors">
        <!-- use ogre2 if ogre v2.x is installed, otherwise use ogre -->
        <render_engine>ogre2</render_engine>
    </plugin>
</gazebo>

<!-- Laser Scanner Plugin -->
<gazebo reference="laser_scan_frame">
    <sensor type="gpu_lidar" name="gpu_lidar">
        <pose relative_to='laser_scan_frame'>0 0 0 0 0 0</pose>
        <gz_frame_id>laser_scan_frame</gz_frame_id>
        <always_on>1</always_on>
        <visualize>true</visualize>
        <update_rate>100</update_rate>
        <topic>laser_scan</topic>
        <ray>
            <scan>
                <horizontal>
                    <samples>200</samples>
                    <resolution>1</resolution>
                    <min_angle>-3.14</min_angle>
                    <max_angle>3.14</max_angle>
                </horizontal>
            </scan>
            <range>
                <min>0.1</min>
                <max>5.0</max>
                <resolution>0.01</resolution>
            </range>
        </ray>
    </sensor>
</gazebo>

  <link name="pointcloud_link">
  </link>

  <joint name="pointcloud_link_joint" type="fixed">
    <origin rpy="0 0 0" xyz="0.051 0.0 0"/>
    <parent link="chassis"/>
    <child link="pointcloud_link"/>
    <axis xyz="0 0 0"/>
  </joint>

<!-- PointCloud Sensor -->
<gazebo reference="pointcloud_link">
    <sensor type="gpu_lidar" name="pointcloud_sensor">
        <pose relative_to="pointcloud_link">0 0 0 0 0 0</pose>
        <!-- Ensure ROS frame_id is clean when bridged -->
        <gz_frame_id>pointcloud_link</gz_frame_id>
        <!-- publish at ~30 Hz and show rays in GUI -->
        <always_on>1</always_on>
        <visualize>true</visualize>
        <update_rate>30</update_rate>
        <!-- Gazebo Transport topic name (not a ROS topic yet) -->
        <topic>pointcloud</topic>
        <ray>
            <scan>
                <horizontal>
                    <samples>50</samples>
                    <resolution>1</resolution>
                    <min_angle>-1.0</min_angle>
                    <max_angle>1.0</max_angle>
                </horizontal>
                <vertical>
                    <samples>50</samples>
                    <resolution>1</resolution>
                    <min_angle>-1.0</min_angle>
                    <max_angle>1.0</max_angle>
                </vertical>
            </scan>
            <range>
                <min>0.10</min>
                <max>5.0</max>
                <resolution>0.01</resolution>
            </range>
        </ray>
    </sensor>
</gazebo>

  <link name="rgb_camera_link_frame">
  </link>

  <joint name="rgb_camera_link_frame_joint" type="fixed">
    <origin rpy="0 0 0" xyz="0.051 0.0 0.05"/>
    <parent link="chassis"/>
    <child link="rgb_camera_link_frame"/>
    <axis xyz="0 0 0"/>
  </joint>

<!-- RGB Wide Angle Camera -->
<gazebo reference="rgb_camera_link_frame">
    <sensor name="camera" type="wideanglecamera">
        <pose relative_to="rgb_camera_link_frame">0 0 0 0 0 0</pose>
        <gz_frame_id>rgb_camera_link_frame</gz_frame_id>
        <always_on>1</always_on>
        <visualize>true</visualize>
        <update_rate>30</update_rate>
        <!-- Base Gazebo Transport topic (not ROS yet) -->
        <topic>rgb_camera</topic>

        <camera>
            <horizontal_fov>6.283</horizontal_fov>
            <image>
                <width>320</width>
                <height>240</height>
                <format>R8G8B8</format>
            </image>
            <clip>
                <near>0.1</near>
                <far>100</far>
            </clip>
            <!-- Wide-angle / fisheye lens settings -->
            <lens>
                <type>custom</type>
                <custom_function>
                    <c1>1.05</c1>
                    <c2>4</c2>
                    <f>1.0</f>
                    <fun>tan</fun>
                </custom_function>
                <scale_to_hfov>true</scale_to_hfov>
                <cutoff_angle>3.1415</cutoff_angle>
                <env_texture_size>512</env_texture_size>
            </lens>
        </camera>
    </sensor>
</gazebo>

</robot>
